Workbook

Sheet Main
A1: Year | B1: Annual Budget | C1: Outside Income | D1: Portfolio Withdrawal to Cover Annual Budget | E1: Total Tax Liability | F1: Taxes as percent of Budgeted Income | G1: Taxable Pool End | H1: Inherited IRA End | I1: Roth IRAs End | J1: Total Net Assets
A2: 2026 | B2: 0 | C2: ='Outside Income'!F2 -> 60338 | D2: =MAX(0, B2-C2) -> 0 | E2: =Taxes!Z2 -> 39820.093 | G2: ='Capital Gains'!I2 -> 3964954.7 | H2: ='Inherited and Roth IRA'!H2 -> 590049.83 | I2: ='Inherited and Roth IRA'!O2 -> 2133346.2 | J2: =SUM(G2:I2) -> 6688350.8
A3: 2027 | B3: 600000 | C3: ='Outside Income'!F3 -> 170117.13 | D3: =MAX(0, B3-C3) -> 429882.87 | E3: =Taxes!Z3 -> 16420.303 | F3: =E3/B3 -> 0.027367172 | G3: ='Capital Gains'!I3 -> 3923929.7 | H3: ='Inherited and Roth IRA'!H3 -> 611965.97 | I3: ='Inherited and Roth IRA'!O3 -> 2346680.8 | J3: =SUM(G3:I3) -> 6882576.6
A4: =A3+1 -> 2028 | B4: =B3*(1+Assumptions!B$11) -> 618000 | C4: ='Outside Income'!F4 -> 173992.85 | D4: =MAX(0, B4-C4) -> 444007.15 | E4: =Taxes!Z4 -> 19162.953 | F4: =E4/B4 -> 0.031008014 | G4: ='Capital Gains'!I4 -> 3862714.1 | H4: ='Inherited and Roth IRA'!H4 -> 632364.83 | I4: ='Inherited and Roth IRA'!O4 -> 2581348.9 | J4: =SUM(G4:I4) -> 7076427.8
A5: =A4+1 -> 2029 | B5: =B4*(1+Assumptions!B$11) -> 636540 | C5: ='Outside Income'!F5 -> 178210.77 | D5: =MAX(0, B5-C5) -> 458329.23 | E5: =Taxes!Z5 -> 22554.339 | F5: =E5/B5 -> 0.035432714 | G5: ='Capital Gains'!I5 -> 3778867.2 | H5: ='Inherited and Roth IRA'!H5 -> 650723.81 | I5: ='Inherited and Roth IRA'!O5 -> 2839483.8 | J5: =SUM(G5:I5) -> 7269074.8
A6: =A5+1 -> 2030 | B6: =B5*(1+Assumptions!B$11) -> 655636.2 | C6: ='Outside Income'!F6 -> 182804.67 | D6: =MAX(0, B6-C6) -> 472831.53 | E6: =Taxes!Z6 -> 26833.551 | F6: =E6/B6 -> 0.040927501 | G6: ='Capital Gains'!I6 -> 3669699.6 | H6: ='Inherited and Roth IRA'!H6 -> 666430.94 | I6: ='Inherited and Roth IRA'!O6 -> 3123432.2 | J6: =SUM(G6:I6) -> 7459562.7
A7: =A6+1 -> 2031 | B7: =B6*(1+Assumptions!B$11) -> 675305.29 | C7: ='Outside Income'!F7 -> 187811.7 | D7: =MAX(0, B7-C7) -> 487493.59 | E7: =Taxes!Z7 -> 30906.741 | F7: =E7/B7 -> 0.045767064 | G7: ='Capital Gains'!I7 -> 3532248.6 | H7: ='Inherited and Roth IRA'!H7 -> 678772.25 | I7: ='Inherited and Roth IRA'!O7 -> 3435775.4 | J7: =SUM(G7:I7) -> 7646796.3
A8: =A7+1 -> 2032 | B8: =B7*(1+Assumptions!B$11) -> 695564.44 | C8: ='Outside Income'!F8 -> 193272.69 | D8: =MAX(0, B8-C8) -> 502291.76 | E8: =Taxes!Z8 -> 30922.417 | F8: =E8/B8 -> 0.044456581 | G8: ='Capital Gains'!I8 -> 3363252.1 | H8: ='Inherited and Roth IRA'!H8 -> 686917.52 | I8: ='Inherited and Roth IRA'!O8 -> 3779353 | J8: =SUM(G8:I8) -> 7829522.6
A9: =A8+1 -> 2033 | B9: =B8*(1+Assumptions!B$11) -> 716431.38 | C9: ='Outside Income'!F9 -> 199232.57 | D9: =MAX(0, B9-C9) -> 517198.8 | E9: =Taxes!Z9 -> 25902.929 | F9: =E9/B9 -> 0.036155491 | G9: ='Capital Gains'!I9 -> 3159119.2 | H9: ='Inherited and Roth IRA'!H9 -> 689904.12 | I9: ='Inherited and Roth IRA'!O9 -> 4157288.3 | J9: =SUM(G9:I9) -> 8006311.6
A10: =A9+1 -> 2034 | B10: =B9*(1+Assumptions!B$11) -> 737924.32 | C10: ='Outside Income'!F10 -> 205740.78 | D10: =MAX(0, B10-C10) -> 532183.54 | E10: =Taxes!Z10 -> 30016.875 | F10: =E10/B10 -> 0.040677444 | G10: ='Capital Gains'!I10 -> 2915898.6 | H10: ='Inherited and Roth IRA'!H10 -> 686618.86 | I10: ='Inherited and Roth IRA'!O10 -> 4573017.1 | J10: =SUM(G10:I10) -> 8175534.5
A11: =A10+1 -> 2035 | B11: =B10*(1+Assumptions!B$11) -> 760062.05 | C11: ='Outside Income'!F11 -> 212851.65 | D11: =MAX(0, B11-C11) -> 547210.4 | E11: =Taxes!Z11 -> 34052.5 | F11: =E11/B11 -> 0.044802263 | G11: ='Capital Gains'!I11 -> 2629243.9 | H11: ='Inherited and Roth IRA'!H11 -> 675777.51 | I11: ='Inherited and Roth IRA'!O11 -> 5030318.8 | J11: =SUM(G11:I11) -> 8335340.2
A12: =A11+1 -> 2036 | B12: =B11*(1+Assumptions!B$11) -> 782863.91 | C12: ='Outside Income'!F12 -> 220624.97 | D12: =MAX(0, B12-C12) -> 562238.94 | E12: =Taxes!Z12 -> 38017.027 | F12: =E12/B12 -> 0.048561477 | G12: ='Capital Gains'!I12 -> 2294375.5 | H12: ='Inherited and Roth IRA'!H12 -> 655901.7 | I12: ='Inherited and Roth IRA'!O12 -> 5533350.7 | J12: =SUM(G12:I12) -> 8483627.9
A13: =A12+1 -> 2037 | B13: =B12*(1+Assumptions!B$11) -> 806349.83 | C13: ='Outside Income'!F13 -> 229126.52 | D13: =MAX(0, B13-C13) -> 577223.31 | E13: =Taxes!Z13 -> 41917.177 | F13: =E13/B13 -> 0.05198386 | G13: ='Capital Gains'!I13 -> 1906038.9 | H13: ='Inherited and Roth IRA'!H13 -> 625292.95 | I13: ='Inherited and Roth IRA'!O13 -> 6086685.8 | J13: =SUM(G13:I13) -> 8618017.6
A14: =A13+1 -> 2038 | B14: =B13*(1+Assumptions!B$11) -> 830540.32 | C14: ='Outside Income'!F14 -> 238428.6 | D14: =MAX(0, B14-C14) -> 592111.72 | E14: =Taxes!Z14 -> 45759.162 | F14: =E14/B14 -> 0.055095653 | G14: ='Capital Gains'!I14 -> 1458459.2 | H14: ='Inherited and Roth IRA'!H14 -> 582003.44 | I14: ='Inherited and Roth IRA'!O14 -> 6695354.3 | J14: =SUM(G14:I14) -> 8735816.9
A15: =A14+1 -> 2039 | B15: =B14*(1+Assumptions!B$11) -> 855456.53 | C15: ='Outside Income'!F15 -> 248610.79 | D15: =MAX(0, B15-C15) -> 606845.74 | E15: =Taxes!Z15 -> 49661.988 | F15: =E15/B15 -> 0.058053199 | G15: ='Capital Gains'!I15 -> 945290.91 | H15: ='Inherited and Roth IRA'!H15 -> 523803.1 | I15: ='Inherited and Roth IRA'!O15 -> 7364889.8 | J15: =SUM(G15:I15) -> 8833983.8
... A31: =A30+1 -> 2055 | B31: =B30*(1+Assumptions!B$11) -> 1372756.6 | C31: ='Outside Income'!F31 -> 152593.06 | D31: =MAX(0, B31-C31) -> 1220163.5 | E31: =Taxes!Z31 -> 0 | F31: =E31/B31 -> 0 | G31: ='Capital Gains'!I31 -> 0 | H31: ='Inherited and Roth IRA'!H31 -> 0 | I31: ='Inherited and Roth IRA'!O31 -> 7623643.7 | J31: =SUM(G31:I31) -> 7623643.7
B33: =SUM(B2:B31) -> 27131310 | C33: =SUM(C2:C31) -> 5692499.8 | D33: =SUM(D2:D31) -> 21499148 | E33: =SUM(E2:E31) -> 575757.71

Sheet Cash Flow
A1: Year | B1: Ilene's Age | C1: Annual Budget | D1: Outside Income | E1: Portfolio Withdrawal to Cover Annual Budget | F1: Taxable Pool Funding | G1: Roth IRA Funding | H1: Inherited IRA Funding | I1: Total Net Assets | J1: Total Taxes Due
A2: 2026 | B2: 65 | C2: =Main!B2 -> 0 | D2: =Main!C2 -> 60338 | E2: =Main!D2 -> 0 | F2: ='Capital Gains'!D2 -> 0 | G2: =MAX(0, E2 - F2) -> 0 | H2: ='Inherited and Roth IRA'!G2 -> 33717.133 | I2: =Main!J2 -> 6688350.8 | J2: =Main!E2 -> 39820.093
A3: =A2+1 -> 2027 | B3: =B2+1 -> 66 | C3: =Main!B3 -> 600000 | D3: =Main!C3 -> 170117.13 | E3: =Main!D3 -> 429882.87 | F3: ='Capital Gains'!D3 -> 429882.87 | G3: =MAX(0, E3 - F3) -> 0 | H3: ='Inherited and Roth IRA'!G3 -> 33717.133 | I3: =Main!J3 -> 6882576.6 | J3: =Main!E3 -> 16420.303
A4: =A3+1 -> 2028 | B4: =B3+1 -> 67 | C4: =Main!B4 -> 618000 | D4: =Main!C4 -> 173992.85 | E4: =Main!D4 -> 444007.15 | F4: ='Capital Gains'!D4 -> 444007.15 | G4: =MAX(0, E4 - F4) -> 0 | H4: ='Inherited and Roth IRA'!G4 -> 37088.846 | I4: =Main!J4 -> 7076427.8 | J4: =Main!E4 -> 19162.953
A5: =A4+1 -> 2029 | B5: =B4+1 -> 68 | C5: =Main!B5 -> 636540 | D5: =Main!C5 -> 178210.77 | E5: =Main!D5 -> 458329.23 | F5: ='Capital Gains'!D5 -> 458329.23 | G5: =MAX(0, E5 - F5) -> 0 | H5: ='Inherited and Roth IRA'!G5 -> 40797.731 | I5: =Main!J5 -> 7269074.8 | J5: =Main!E5 -> 22554.339
A6: =A5+1 -> 2030 | B6: =B5+1 -> 69 | C6: =Main!B6 -> 655636.2 | D6: =Main!C6 -> 182804.67 | E6: =Main!D6 -> 472831.53 | F6: ='Capital Gains'!D6 -> 472831.53 | G6: =MAX(0, E6 - F6) -> 0 | H6: ='Inherited and Roth IRA'!G6 -> 44877.504 | I6: =Main!J6 -> 7459562.7 | J6: =Main!E6 -> 26833.551
A7: =A6+1 -> 2031 | B7: =B6+1 -> 70 | C7: =Main!B7 -> 675305.29 | D7: =Main!C7 -> 187811.7 | E7: =Main!D7 -> 487493.59 | F7: ='Capital Gains'!D7 -> 487493.59 | G7: =MAX(0, E7 - F7) -> 0 | H7: ='Inherited and Roth IRA'!G7 -> 49365.255 | I7: =Main!J7 -> 7646796.3 | J7: =Main!E7 -> 30906.741
A8: =A7+1 -> 2032 | B8: =B7+1 -> 71 | C8: =Main!B8 -> 695564.44 | D8: =Main!C8 -> 193272.69 | E8: =Main!D8 -> 502291.76 | F8: ='Capital Gains'!D8 -> 502291.76 | G8: =MAX(0, E8 - F8) -> 0 | H8: ='Inherited and Roth IRA'!G8 -> 54301.78 | I8: =Main!J8 -> 7829522.6 | J8: =Main!E8 -> 30922.417
A9: =A8+1 -> 2033 | B9: =B8+1 -> 72 | C9: =Main!B9 -> 716431.38 | D9: =Main!C9 -> 199232.57 | E9: =Main!D9 -> 517198.8 | F9: ='Capital Gains'!D9 -> 517198.8 | G9: =MAX(0, E9 - F9) -> 0 | H9: ='Inherited and Roth IRA'!G9 -> 59731.958 | I9: =Main!J9 -> 8006311.6 | J9: =Main!E9 -> 25902.929
A10: =A9+1 -> 2034 | B10: =B9+1 -> 73 | C10: =Main!B10 -> 737924.32 | D10: =Main!C10 -> 205740.78 | E10: =Main!D10 -> 532183.54 | F10: ='Capital Gains'!D10 -> 532183.54 | G10: =MAX(0, E10 - F10) -> 0 | H10: ='Inherited and Roth IRA'!G10 -> 65705.154 | I10: =Main!J10 -> 8175534.5 | J10: =Main!E10 -> 30016.875
A11: =A10+1 -> 2035 | B11: =B10+1 -> 74 | C11: =Main!B11 -> 760062.05 | D11: =Main!C11 -> 212851.65 | E11: =Main!D11 -> 547210.4 | F11: ='Capital Gains'!D11 -> 547210.4 | G11: =MAX(0, E11 - F11) -> 0 | H11: ='Inherited and Roth IRA'!G11 -> 72275.669 | I11: =Main!J11 -> 8335340.2 | J11: =Main!E11 -> 34052.5
A12: =A11+1 -> 2036 | B12: =B11+1 -> 75 | C12: =Main!B12 -> 782863.91 | D12: =Main!C12 -> 220624.97 | E12: =Main!D12 -> 562238.94 | F12: ='Capital Gains'!D12 -> 562238.94 | G12: =MAX(0, E12 - F12) -> 0 | H12: ='Inherited and Roth IRA'!G12 -> 79503.236 | I12: =Main!J12 -> 8483627.9 | J12: =Main!E12 -> 38017.027
A13: =A12+1 -> 2037 | B13: =B12+1 -> 76 | C13: =Main!B13 -> 806349.83 | D13: =Main!C13 -> 229126.52 | E13: =Main!D13 -> 577223.31 | F13: ='Capital Gains'!D13 -> 577223.31 | G13: =MAX(0, E13 - F13) -> 0 | H13: ='Inherited and Roth IRA'!G13 -> 87453.56 | I13: =Main!J13 -> 8618017.6 | J13: =Main!E13 -> 41917.177
A14: =A13+1 -> 2038 | B14: =B13+1 -> 77 | C14: =Main!B14 -> 830540.32 | D14: =Main!C14 -> 238428.6 | E14: =Main!D14 -> 592111.72 | F14: ='Capital Gains'!D14 -> 592111.72 | G14: =MAX(0, E14 - F14) -> 0 | H14: ='Inherited and Roth IRA'!G14 -> 96198.916 | I14: =Main!J14 -> 8735816.9 | J14: =Main!E14 -> 45759.162
... A31: =A30+1 -> 2055 | B31: =B30+1 -> 94 | C31: =Main!B31 -> 1372756.6 | D31: =Main!C31 -> 152593.06 | E31: =Main!D31 -> 1220163.5 | F31: ='Capital Gains'!D31 -> 0 | G31: =MAX(0, E31 - F31) -> 1220163.5 | H31: ='Inherited and Roth IRA'!G31 -> 0 | I31: =Main!J31 -> 7623643.7 | J31: =Main!E31 -> 0
C33: =SUM(C2:C31) -> 27131310 | D33: =SUM(D2:D31) -> 5692499.8 | E33: =SUM(E2:E31) -> 21499148 | F33: =SUM(F2:F31) -> 7710771.9 | G33: =SUM(G2:G31) -> 13788376 | H33: =SUM(H2:H31) -> 1485979.4 | J33: =SUM(J2:J31) -> 575757.71

Sheet Assumptions
D1: Price per share | E1: Number of Shares | F1: Appreciation in Remainder of 2026 | G1: 2026 Year-end balance
A2: Initial Taxable Pool | B2: 3803339 | C2: Opening balance | D2: 89.3096 | E2: =B2/D2 -> 42586.004 | F2: =(B2*B5)*C7 -> 161615.7 | G2: =B2+F2 -> 3964954.7
A3: Initial Inherited IRA Pool | B3: 600567 | C3: Opening balance | D3: 45.53 | E3: =B3/D3 -> 13190.578 | F3: =(B3*B$8)*C7 -> 23199.963 | G3: =B3+F3 -> 623766.96
A4: Initial Roth IRA Pool | B4: 2054000 | C4: Opening balance | D4: 45.53 | E4: =B4/D4 -> 45113.112 | F4: =(B4*B$8)*C7 -> 79346.225 | G4: =B4+F4 -> 2133346.2
A5: Vanguard VUG annual return | B5: 0.11 | C5: =B5*0.0416666 -> 0.004583326
A6: VUG annual dividend | B6: 0.0043
A7: Maximum cap on Viatar business losses | B7: 400000 | C7: 0.386301 | D7: Prorate appreciation from 8-15 to 12-31-2026
A8: Vanguard VLXVX annual return | B8: 0.1
A9: Margin Debt Interest Rate | B9: 0.065
A10: Out-of-Pocket Tax Ceiling | B10: 35000
A11: Budget Inflation Rate | B11: 0.03
A12: Combined Ordinary Tax Rate | B12: 0.2837
A13: NJ Personal & Senior Exemptions (MFJ Age 65+) | B13: 4000
A14: NJ tax rate | B14: 0.0675
A15: Max Extra IRA Paydown Cap | B15: 150000
A16: VUG opening balance stock price | B16: 83.48
A17: VLXVX opening balance stock price | B17: 43.74
A18: NJ BRACKETS (MFJ) | B18: Bracket Start | C18: Marginal Rate | D18: Base Tax Amount | E18: Description
A20: NJ Bracket 1 | B20: 0 | C20: 0.014 | D20: 0 | E20: $0 to $20,000
A21: NJ Bracket 2 | B21: 20000 | C21: 0.0175 | D21: 280 | E21: $20,001 to $50,000
A22: NJ Bracket 3 | B22: 50000 | C22: 0.0245 | D22: 805 | E22: $50,001 to $70,000
A23: NJ Bracket 4 | B23: 70000 | C23: 0.035 | D23: 1295.5 | E23: $70,001 to $80,000
A24: NJ Bracket 5 | B24: 80000 | C24: 0.0553 | D24: 1645 | E24: $80,001 to $150,000
A25: NJ Bracket 6 | B25: 150000 | C25: 0.0637 | D25: 5512.5 | E25: $150,001 to $500,000
A26: NJ Bracket 7 | B26: 500000 | C26: 0.0897 | D26: 27807.5 | E26: $500,001 to $1,000,000
A27: NJ Bracket 8 | B27: 1000000 | C27: 0.1075 | D27: 72657.5 | E27: Over $1,000,000
A28: Accelerated IRA Target Draw | B28: 0
A29: FEDERAL ORDINARY INCOME TAX BRACKETS (2026 MFJ) | B29: Bracket Start | C29: Marginal Rate | D29: Base Tax Amount | E29: Taxable Income Range Description
A30: Fed Ord Bracket 1 | B30: 0 | C30: 0.1 | D30: 0 | E30: 10% Rate ($0 to $23,200)
A31: Fed Ord Bracket 2 | B31: 23200 | C31: 0.12 | D31: 2320 | E31: 12% Rate ($23,201 to $94,300)
A32: Fed Ord Bracket 3 | B32: 94300 | C32: 0.22 | D32: 10852 | E32: 22% Rate ($94,301 to $201,050)
A33: Fed Ord Bracket 4 | B33: 201050 | C33: 0.24 | D33: 34337 | E33: 24% Rate ($201,051 to $383,900)
A34: Fed Ord Bracket 5 | B34: 383900 | C34: 0.32 | D34: 78221 | E34: 32% Rate ($383,901 to $487,450)
A35: Fed Ord Bracket 6 | B35: 487450 | C35: 0.35 | D35: 111357 | E35: 35% Rate ($487,451 to $731,200)
A36: Fed Ord Bracket 7 | B36: 731200 | C36: 0.37 | D36: 196669.5 | E36: 37% Rate (Over $731,200)
A37: IRC § 163(d) Capital Gains Election Amount
A39: FEDERAL CAPITAL GAINS TAX BRACKETS (2026 MFJ) | B39: Bracket Start | C39: Marginal Rate | D39: Base Tax Amount | E39: Taxable Income Range Description
A40: Fed CG Bracket 1 | B40: 0 | C40: 0 | D40: 0 | E40: 0% Rate ($0 to $94,050)
A41: Fed CG Bracket 2 | B41: 94050 | C41: 0.15 | D41: 0 | E41: 15% Rate ($94,051 to $583,750)
A42: Fed CG Bracket 3 | B42: 583750 | C42: 0.2 | D42: 73455 | E42: 20% Rate (Over $583,750)
...

Sheet Taxes
A1: Year | B1: Social Security Taxable Portion | C1: Inherited IRA Distributions | D1: Dividend Income | E1: Roth Conversion Income | F1: Optimal § 163(d) Election | G1: Federal Gross Ordinary Income | H1: Viatar Business Loss | I1: Federal Net Ordinary Income | J1: Unabsorbed Viatar Loss | K1: Realized Capital Gains | L1: Capital Gains After Viatar Loss | M1: Adjusted Gross Income (AGI) | N1: Schedule A Itemized Deductions | O1: Taxable Ordinary Income | P1: Federal Tax on Ordinary Income | Q1: Realized Capital Gains (Baseline) | R1: Investment Interest Carryforward Applied to LTCG | S1: Unused Schedule A Deduction | T1: Capital Gains Subject to LTCG Tax | U1: Federal Capital Gains Tax | V1: 3.8% Medicare Surtax / NIIT (IRC § 1411) | W1: Gross Federal Tax Liability | X1: NJ Taxable Income | Y1: NJ Tax Liability | Z1: Total Federal and NJ Taxes | AA1: Viatar Total Loss Applied
A2: 2026 | B2: ='Outside Income'!D2 * 0.85 -> 27268 | C2: ='Outside Income'!E2 -> 28258 | D2: =IF('Capital Gains'!G2<=0, 0, 'Outside Income'!G2) -> 48872 | E2: ='Inherited and Roth IRA'!K2 -> 200000 | F2: =IF('Capital Gains'!F2<=0, 0, MIN(MAX(0, 'Schedule A'!P2 - D2), 'Capital Gains'!F2)) -> 38918 | G2: =B2 + C2 + D2 + E2 + F2 -> 343316 | H2: =MAX(0, MIN(400000, G2 - ((20000 + 'Schedule A'!J2 + 'Schedule A'!K2 + 'Schedule A'!L2 + 'Schedule A'!Q2 + 'Schedule A'!C2 - 0.075 * MAX(0, K2 - F2)) / 1.075))) -> 161821.12 | I2: =MAX(0, G2 - H2) -> 181494.88 | J2: =MAX(0, 400000 - G2) -> 56684 | K2: =IF('Capital Gains'!G2<=0, 0, MAX(0, 'Capital Gains'!F2 - F2)) -> 274598 | L2: =IF('Capital Gains'!G2<=0, 0, MAX(0, K2 - J2)) -> 217914 | M2: =I2 + L2 -> 399408.88 | N2: ='Schedule A'!M2 -> 162827.33 | O2: =MAX(0, I2 - N2) -> 18667.55 | P2: =IF(O2<=0, 0, IF(O2<=Assumptions!$B$30, O2*Assumptions!$C$29, IF(O2<=Assumptions!$B$31, Assumptions!$D$30 + (O2-Assumptions!$B$30)*Assumptions!$C$30, IF(O2<=Assumptions!$B$32, Assumptions!$D$31 + (O2-Assumptions!$B$31)*Assumptions!$C$31, IF(O2<=Assumptions!$B$33, Assumptions!$D$32 + (O2-Assumptions!$B$32)*Assumptions!$C$32, IF(O2<=Assumptions!$B$34, Assumptions!$D$33 + (O2-Assumptions!$B$33)*Assumptions!$C$33, IF(O2<=Assumptions!$B$35, Assumptions!$D$34 + (O2-Assumptions!$B$34)*Assumptions!$C$34, Assumptions!$D$35 + (O2-Assumptions!$B$35)*Assumptions!$C$35))))))) -> 1866.755 | Q2: =L2 -> 217914 | R2: =IF('Capital Gains'!G2<=0, 0, MIN('Schedule A'!R2, L2)) -> 0 | S2: =MAX(0, N2 - I2) -> 0 | T2: =IF('Capital Gains'!G2<=0, 0, MAX(0, L2 - S2)) -> 217914 | U2: =IF(T2<=0, 0, IF((O2+T2)<=Assumptions!$B$46, 0, IF(O2>=Assumptions!$B$46, T2*Assumptions!$C$46, (O2+T2-Assumptions!$B$46)*Assumptions!$C$46))) -> 0 | V2: =IF(M2<=250000, 0, 0.038 * MIN(M2 - 250000, D2 + T2)) -> 5677.5376 | W2: =P2 + U2 + V2 -> 7544.2926 | X2: =C2 + D2 + E2 + 'Capital Gains'!F2 -> 590646 | Y2: =IF(MAX(0, X2 - 20500)<=0, 0, IF(MAX(0, X2 - 20500)<=Assumptions!$B$20, MAX(0, X2 - 20500)*Assumptions!$C$19, IF(MAX(0, X2 - 20500)<=Assumptions!$B$21, Assumptions!$D$20 + (MAX(0, X2 - 20500)-Assumptions!$B$20)*Assumptions!$C$20, IF(MAX(0, X2 - 20500)<=Assumptions!$B$22, Assumptions!$D$21 + (MAX(0, X2 - 20500)-Assumptions!$B$21)*Assumptions!$C$21, IF(MAX(0, X2 - 20500)<=Assumptions!$B$23, Assumptions!$D$22 + (MAX(0, X2 - 20500)-Assumptions!$B$22)*Assumptions!$C$22, IF(MAX(0, X2 - 20500)<=Assumptions!$B$24, Assumptions!$D$23 + (MAX(0, X2 - 20500)-Assumptions!$B$23)*Assumptions!$C$23, IF(MAX(0, X2 - 20500)<=Assumptions!$B$25, Assumptions!$D$24 + (MAX(0, X2 - 20500)-Assumptions!$B$25)*Assumptions!$C$24, Assumptions!$D$25 + (MAX(0, X2 - 20500)-Assumptions!$B$25)*Assumptions!$C$25))))))) -> 32275.8 | Z2: =W2 + Y2 -> 39820.093 | AA2: =H2 + MIN(J2, 'Capital Gains'!F2) -> 218505.12
A3: 2027 | B3: ='Outside Income'!D3 * 0.85 -> 42840 | C3: ='Outside Income'!E3 -> 33717.133 | D3: =IF('Capital Gains'!G3<=0, 0, 'Outside Income'!G3) -> 17049.305 | E3: ='Inherited and Roth IRA'!K3 -> 200000 | F3: =IF('Capital Gains'!F3<=0, 0, MIN(MAX(0, 'Schedule A'!P3 - D3), 'Capital Gains'!F3)) -> 59573.491 | G3: =B3 + C3 + D3 + E3 + F3 -> 353179.93 | H3: =MAX(0, MIN(400000, G3 - ((20000 + 'Schedule A'!J3 + 'Schedule A'!K3 + 'Schedule A'!L3 + 'Schedule A'!Q3 + 'Schedule A'!C3 - 0.075 * MAX(0, K3 - F3)) / 1.075))) -> 165630.35 | I3: =MAX(0, G3 - H3) -> 187549.58 | J3: =MAX(0, 400000 - G3) -> 46820.071 | K3: =IF('Capital Gains'!G3<=0, 0, MAX(0, 'Capital Gains'!F3 - F3)) -> 0 | L3: =IF('Capital Gains'!G3<=0, 0, MAX(0, K3 - J3)) -> 0 | M3: =I3 + L3 -> 187549.58 | N3: ='Schedule A'!M3 -> 167549.58 | O3: =MAX(0, I3 - N3) -> 20000 | P3: =IF(O3<=0, 0, IF(O3<=Assumptions!$B$30, O3*Assumptions!$C$29, IF(O3<=Assumptions!$B$31, Assumptions!$D$30 + (O3-Assumptions!$B$30)*Assumptions!$C$30, IF(O3<=Assumptions!$B$32, Assumptions!$D$31 + (O3-Assumptions!$B$31)*Assumptions!$C$31, IF(O3<=Assumptions!$B$33, Assumptions!$D$32 + (O3-Assumptions!$B$32)*Assumptions!$C$32, IF(O3<=Assumptions!$B$34, Assumptions!$D$33 + (O3-Assumptions!$B$33)*Assumptions!$C$33, IF(O3<=Assumptions!$B$35, Assumptions!$D$34 + (O3-Assumptions!$B$34)*Assumptions!$C$34, Assumptions!$D$35 + (O3-Assumptions!$B$35)*Assumptions!$C$35))))))) -> 2000 | Q3: =L3 -> 0 | R3: =IF('Capital Gains'!G3<=0, 0, MIN('Schedule A'!R3, L3)) -> 0 | S3: =MAX(0, N3 - I3) -> 0 | T3: =IF('Capital Gains'!G3<=0, 0, MAX(0, L3 - S3)) -> 0 | U3: =IF(T3<=0, 0, IF((O3+T3)<=Assumptions!$B$46, 0, IF(O3>=Assumptions!$B$46, T3*Assumptions!$C$46, (O3+T3-Assumptions!$B$46)*Assumptions!$C$46))) -> 0 | V3: =IF(M3<=250000, 0, 0.038 * MIN(M3 - 250000, D3 + T3)) -> 0 | W3: =P3 + U3 + V3 -> 2000 | X3: =C3 + D3 + E3 + 'Capital Gains'!F3 -> 310339.93 | Y3: =IF(MAX(0, X3 - 20500)<=0, 0, IF(MAX(0, X3 - 20500)<=Assumptions!$B$20, MAX(0, X3 - 20500)*Assumptions!$C$19, IF(MAX(0, X3 - 20500)<=Assumptions!$B$21, Assumptions!$D$20 + (MAX(0, X3 - 20500)-Assumptions!$B$20)*Assumptions!$C$20, IF(MAX(0, X3 - 20500)<=Assumptions!$B$22, Assumptions!$D$21 + (MAX(0, X3 - 20500)-Assumptions!$B$21)*Assumptions!$C$21, IF(MAX(0, X3 - 20500)<=Assumptions!$B$23, Assumptions!$D$22 + (MAX(0, X3 - 20500)-Assumptions!$B$22)*Assumptions!$C$22, IF(MAX(0, X3 - 20500)<=Assumptions!$B$24, Assumptions!$D$23 + (MAX(0, X3 - 20500)-Assumptions!$B$23)*Assumptions!$C$23, IF(MAX(0, X3 - 20500)<=Assumptions!$B$25, Assumptions!$D$24 + (MAX(0, X3 - 20500)-Assumptions!$B$25)*Assumptions!$C$24, Assumptions!$D$25 + (MAX(0, X3 - 20500)-Assumptions!$B$25)*Assumptions!$C$25))))))) -> 14420.303 | Z3: =W3 + Y3 -> 16420.303 | AA3: =H3 + MIN(J3, 'Capital Gains'!F3) -> 212450.42
A4: 2028 | B4: ='Outside Income'!D4 * 0.85 -> 43268.4 | C4: ='Outside Income'!E4 -> 37088.846 | D4: =IF('Capital Gains'!G4<=0, 0, 'Outside Income'!G4) -> 16872.898 | E4: ='Inherited and Roth IRA'!K4 -> 200000 | F4: =IF('Capital Gains'!F4<=0, 0, MIN(MAX(0, 'Schedule A'!P4 - D4), 'Capital Gains'!F4)) -> 99433.903 | G4: =B4 + C4 + D4 + E4 + F4 -> 396664.05 | H4: =MAX(0, MIN(400000, G4 - ((20000 + 'Schedule A'!J4 + 'Schedule A'!K4 + 'Schedule A'!L4 + 'Schedule A'!Q4 + 'Schedule A'!C4 - 0.075 * MAX(0, K4 - F4)) / 1.075))) -> 172199.12 | I4: =MAX(0, G4 - H4) -> 224464.93 | J4: =MAX(0, 400000 - G4) -> 3335.9531 | K4: =IF('Capital Gains'!G4<=0, 0, MAX(0, 'Capital Gains'!F4 - F4)) -> 0 | L4: =IF('Capital Gains'!G4<=0, 0, MAX(0, K4 - J4)) -> 0 | M4: =I4 + L4 -> 224464.93 | N4: ='Schedule A'!M4 -> 204464.93 | O4: =MAX(0, I4 - N4) -> 20000 | P4: =IF(O4<=0, 0, IF(O4<=Assumptions!$B$30, O4*Assumptions!$C$29, IF(O4<=Assumptions!$B$31, Assumptions!$D$30 + (O4-Assumptions!$B$30)*Assumptions!$C$30, IF(O4<=Assumptions!$B$32, Assumptions!$D$31 + (O4-Assumptions!$B$31)*Assumptions!$C$31, IF(O4<=Assumptions!$B$33, Assumptions!$D$32 + (O4-Assumptions!$B$32)*Assumptions!$C$32, IF(O4<=Assumptions!$B$34, Assumptions!$D$33 + (O4-Assumptions!$B$33)*Assumptions!$C$33, IF(O4<=Assumptions!$B$35, Assumptions!$D$34 + (O4-Assumptions!$B$34)*Assumptions!$C$34, Assumptions!$D$35 + (O4-Assumptions!$B$35)*Assumptions!$C$35))))))) -> 2000 | Q4: =L4 -> 0 | R4: =IF('Capital Gains'!G4<=0, 0, MIN('Schedule A'!R4, L4)) -> 0 | S4: =MAX(0, N4 - I4) -> 0 | T4: =IF('Capital Gains'!G4<=0, 0, MAX(0, L4 - S4)) -> 0 | U4: =IF(T4<=0, 0, IF((O4+T4)<=Assumptions!$B$46, 0, IF(O4>=Assumptions!$B$46, T4*Assumptions!$C$46, (O4+T4-Assumptions!$B$46)*Assumptions!$C$46))) -> 0 | V4: =IF(M4<=250000, 0, 0.038 * MIN(M4 - 250000, D4 + T4)) -> 0 | W4: =P4 + U4 + V4 -> 2000 | X4: =C4 + D4 + E4 + 'Capital Gains'!F4 -> 353395.65 | Y4: =IF(MAX(0, X4 - 20500)<=0, 0, IF(MAX(0, X4 - 20500)<=Assumptions!$B$20, MAX(0, X4 - 20500)*Assumptions!$C$19, IF(MAX(0, X4 - 20500)<=Assumptions!$B$21, Assumptions!$D$20 + (MAX(0, X4 - 20500)-Assumptions!$B$20)*Assumptions!$C$20, IF(MAX(0, X4 - 20500)<=Assumptions!$B$22, Assumptions!$D$21 + (MAX(0, X4 - 20500)-Assumptions!$B$21)*Assumptions!$C$21, IF(MAX(0, X4 - 20500)<=Assumptions!$B$23, Assumptions!$D$22 + (MAX(0, X4 - 20500)-Assumptions!$B$22)*Assumptions!$C$22, IF(MAX(0, X4 - 20500)<=Assumptions!$B$24, Assumptions!$D$23 + (MAX(0, X4 - 20500)-Assumptions!$B$23)*Assumptions!$C$23, IF(MAX(0, X4 - 20500)<=Assumptions!$B$25, Assumptions!$D$24 + (MAX(0, X4 - 20500)-Assumptions!$B$25)*Assumptions!$C$24, Assumptions!$D$25 + (MAX(0, X4 - 20500)-Assumptions!$B$25)*Assumptions!$C$25))))))) -> 17162.953 | Z4: =W4 + Y4 -> 19162.953 | AA4: =H4 + MIN(J4, 'Capital Gains'!F4) -> 175535.07
A5: 2029 | B5: ='Outside Income'!D5 * 0.85 -> 43701.084 | C5: ='Outside Income'!E5 -> 40797.731 | D5: =IF('Capital Gains'!G5<=0, 0, 'Outside Income'!G5) -> 16609.67 | E5: ='Inherited and Roth IRA'!K5 -> 200000 | F5: =IF('Capital Gains'!F5<=0, 0, MIN(MAX(0, 'Schedule A'!P5 - D5), 'Capital Gains'!F5)) -> 104145.73 | G5: =B5 + C5 + D5 + E5 + F5 -> 405254.21 | H5: =MAX(0, MIN(400000, G5 - ((20000 + 'Schedule A'!J5 + 'Schedule A'!K5 + 'Schedule A'!L5 + 'Schedule A'!Q5 + 'Schedule A'!C5 - 0.075 * MAX(0, K5 - F5)) / 1.075))) -> 176651.05 | I5: =MAX(0, G5 - H5) -> 228603.16 | J5: =MAX(0, 400000 - G5) -> 0 | K5: =IF('Capital Gains'!G5<=0, 0, MAX(0, 'Capital Gains'!F5 - F5)) -> 33743.91 | L5: =IF('Capital Gains'!G5<=0, 0, MAX(0, K5 - J5)) -> 33743.91 | M5: =I5 + L5 -> 262347.07 | N5: ='Schedule A'!M5 -> 206072.37 | O5: =MAX(0, I5 - N5) -> 22530.793 | P5: =IF(O5<=0, 0, IF(O5<=Assumptions!$B$30, O5*Assumptions!$C$29, IF(O5<=Assumptions!$B$31, Assumptions!$D$30 + (O5-Assumptions!$B$30)*Assumptions!$C$30, IF(O5<=Assumptions!$B$32, Assumptions!$D$31 + (O5-Assumptions!$B$31)*Assumptions!$C$31, IF(O5<=Assumptions!$B$33, Assumptions!$D$32 + (O5-Assumptions!$B$32)*Assumptions!$C$32, IF(O5<=Assumptions!$B$34, Assumptions!$D$33 + (O5-Assumptions!$B$33)*Assumptions!$C$33, IF(O5<=Assumptions!$B$35, Assumptions!$D$34 + (O5-Assumptions!$B$34)*Assumptions!$C$34, Assumptions!$D$35 + (O5-Assumptions!$B$35)*Assumptions!$C$35))))))) -> 2253.0793 | Q5: =L5 -> 33743.91 | R5: =IF('Capital Gains'!G5<=0, 0, MIN('Schedule A'!R5, L5)) -> 0 | S5: =MAX(0, N5 - I5) -> 0 | T5: =IF('Capital Gains'!G5<=0, 0, MAX(0, L5 - S5)) -> 33743.91 | U5: =IF(T5<=0, 0, IF((O5+T5)<=Assumptions!$B$46, 0, IF(O5>=Assumptions!$B$46, T5*Assumptions!$C$46, (O5+T5-Assumptions!$B$46)*Assumptions!$C$46))) -> 0 | V5: =IF(M5<=250000, 0, 0.038 * MIN(M5 - 250000, D5 + T5)) -> 469.18871 | W5: =P5 + U5 + V5 -> 2722.268 | X5: =C5 + D5 + E5 + 'Capital Gains'!F5 -> 395297.04 | Y5: =IF(MAX(0, X5 - 20500)<=0, 0, IF(MAX(0, X5 - 20500)<=Assumptions!$B$20, MAX(0, X5 - 20500)*Assumptions!$C$19, IF(MAX(0, X5 - 20500)<=Assumptions!$B$21, Assumptions!$D$20 + (MAX(0, X5 - 20500)-Assumptions!$B$20)*Assumptions!$C$20, IF(MAX(0, X5 - 20500)<=Assumptions!$B$22, Assumptions!$D$21 + (MAX(0, X5 - 20500)-Assumptions!$B$21)*Assumptions!$C$21, IF(MAX(0, X5 - 20500)<=Assumptions!$B$23, Assumptions!$D$22 + (MAX(0, X5 - 20500)-Assumptions!$B$22)*Assumptions!$C$22, IF(MAX(0, X5 - 20500)<=Assumptions!$B$24, Assumptions!$D$23 + (MAX(0, X5 - 20500)-Assumptions!$B$23)*Assumptions!$C$23, IF(MAX(0, X5 - 20500)<=Assumptions!$B$25, Assumptions!$D$24 + (MAX(0, X5 - 20500)-Assumptions!$B$25)*Assumptions!$C$24, Assumptions!$D$25 + (MAX(0, X5 - 20500)-Assumptions!$B$25)*Assumptions!$C$25))))))) -> 19832.071 | Z5: =W5 + Y5 -> 22554.339 | AA5: =H5 + MIN(J5, 'Capital Gains'!F5) -> 176651.05
A6: 2030 | B6: ='Outside Income'!D6 * 0.85 -> 44138.095 | C6: ='Outside Income'!E6 -> 44877.504 | D6: =IF('Capital Gains'!G6<=0, 0, 'Outside Income'!G6) -> 16249.129 | E6: ='Inherited and Roth IRA'!K6 -> 200000 | F6: =IF('Capital Gains'!F6<=0, 0, MIN(MAX(0, 'Schedule A'!P6 - D6), 'Capital Gains'!F6)) -> 107673.62 | G6: =B6 + C6 + D6 + E6 + F6 -> 412938.35 | H6: =MAX(0, MIN(400000, G6 - ((20000 + 'Schedule A'!J6 + 'Schedule A'!K6 + 'Schedule A'!L6 + 'Schedule A'!Q6 + 'Schedule A'!C6 - 0.075 * MAX(0, K6 - F6)) / 1.075))) -> 181388.81 | I6: =MAX(0, G6 - H6) -> 231549.53 | J6: =MAX(0, 400000 - G6) -> 0 | K6: =IF('Capital Gains'!G6<=0, 0, MAX(0, 'Capital Gains'!F6 - F6)) -> 67339.138 | L6: =IF('Capital Gains'!G6<=0, 0, MAX(0, K6 - J6)) -> 67339.138 | M6: =I6 + L6 -> 298888.67 | N6: ='Schedule A'!M6 -> 206499.1 | O6: =MAX(0, I6 - N6) -> 25050.435 | P6: =IF(O6<=0, 0, IF(O6<=Assumptions!$B$30, O6*Assumptions!$C$29, IF(O6<=Assumptions!$B$31, Assumptions!$D$30 + (O6-Assumptions!$B$30)*Assumptions!$C$30, IF(O6<=Assumptions!$B$32, Assumptions!$D$31 + (O6-Assumptions!$B$31)*Assumptions!$C$31, IF(O6<=Assumptions!$B$33, Assumptions!$D$32 + (O6-Assumptions!$B$32)*Assumptions!$C$32, IF(O6<=Assumptions!$B$34, Assumptions!$D$33 + (O6-Assumptions!$B$33)*Assumptions!$C$33, IF(O6<=Assumptions!$B$35, Assumptions!$D$34 + (O6-Assumptions!$B$34)*Assumptions!$C$34, Assumptions!$D$35 + (O6-Assumptions!$B$35)*Assumptions!$C$35))))))) -> 2542.0522 | Q6: =L6 -> 67339.138 | R6: =IF('Capital Gains'!G6<=0, 0, MIN('Schedule A'!R6, L6)) -> 0 | S6: =MAX(0, N6 - I6) -> 0 | T6: =IF('Capital Gains'!G6<=0, 0, MAX(0, L6 - S6)) -> 67339.138 | U6: =IF(T6<=0, 0, IF((O6+T6)<=Assumptions!$B$46, 0, IF(O6>=Assumptions!$B$46, T6*Assumptions!$C$46, (O6+T6-Assumptions!$B$46)*Assumptions!$C$46))) -> 0 | V6: =IF(M6<=250000, 0, 0.038 * MIN(M6 - 250000, D6 + T6)) -> 1857.7696 | W6: =P6 + U6 + V6 -> 4399.8218 | X6: =C6 + D6 + E6 + 'Capital Gains'!F6 -> 436139.39 | Y6: =IF(MAX(0, X6 - 20500)<=0, 0, IF(MAX(0, X6 - 20500)<=Assumptions!$B$20, MAX(0, X6 - 20500)*Assumptions!$C$19, IF(MAX(0, X6 - 20500)<=Assumptions!$B$21, Assumptions!$D$20 + (MAX(0, X6 - 20500)-Assumptions!$B$20)*Assumptions!$C$20, IF(MAX(0, X6 - 20500)<=Assumptions!$B$22, Assumptions!$D$21 + (MAX(0, X6 - 20500)-Assumptions!$B$21)*Assumptions!$C$21, IF(MAX(0, X6 - 20500)<=Assumptions!$B$23, Assumptions!$D$22 + (MAX(0, X6 - 20500)-Assumptions!$B$22)*Assumptions!$C$22, IF(MAX(0, X6 - 20500)<=Assumptions!$B$24, Assumptions!$D$23 + (MAX(0, X6 - 20500)-Assumptions!$B$23)*Assumptions!$C$23, IF(MAX(0, X6 - 20500)<=Assumptions!$B$25, Assumptions!$D$24 + (MAX(0, X6 - 20500)-Assumptions!$B$25)*Assumptions!$C$24, Assumptions!$D$25 + (MAX(0, X6 - 20500)-Assumptions!$B$25)*Assumptions!$C$25))))))) -> 22433.729 | Z6: =W6 + Y6 -> 26833.551 | AA6: =H6 + MIN(J6, 'Capital Gains'!F6) -> 181388.81
A7: 2031 | B7: ='Outside Income'!D7 * 0.85 -> 44579.476 | C7: ='Outside Income'!E7 -> 49365.255 | D7: =IF('Capital Gains'!G7<=0, 0, 'Outside Income'!G7) -> 15779.708 | E7: ='Inherited and Roth IRA'!K7 -> 200000 | F7: =IF('Capital Gains'!F7<=0, 0, MIN(MAX(0, 'Schedule A'!P7 - D7), 'Capital Gains'!F7)) -> 119296.09 | G7: =B7 + C7 + D7 + E7 + F7 -> 429020.53 | H7: =MAX(0, MIN(400000, G7 - ((20000 + 'Schedule A'!J7 + 'Schedule A'!K7 + 'Schedule A'!L7 + 'Schedule A'!Q7 + 'Schedule A'!C7 - 0.075 * MAX(0, K7 - F7)) / 1.075))) -> 187096.07 | I7: =MAX(0, G7 - H7) -> 241924.46 | J7: =MAX(0, 400000 - G7) -> 0 | K7: =IF('Capital Gains'!G7<=0, 0, MAX(0, 'Capital Gains'!F7 - F7)) -> 91572.412 | L7: =IF('Capital Gains'!G7<=0, 0, MAX(0, K7 - J7)) -> 91572.412 | M7: =I7 + L7 -> 333496.87 | N7: ='Schedule A'!M7 -> 215056.53 | O7: =MAX(0, I7 - N7) -> 26867.931 | P7: =IF(O7<=0, 0, IF(O7<=Assumptions!$B$30, O7*Assumptions!$C$29, IF(O7<=Assumptions!$B$31, Assumptions!$D$30 + (O7-Assumptions!$B$30)*Assumptions!$C$30, IF(O7<=Assumptions!$B$32, Assumptions!$D$31 + (O7-Assumptions!$B$31)*Assumptions!$C$31, IF(O7<=Assumptions!$B$33, Assumptions!$D$32 + (O7-Assumptions!$B$32)*Assumptions!$C$32, IF(O7<=Assumptions!$B$34, Assumptions!$D$33 + (O7-Assumptions!$B$33)*Assumptions!$C$33, IF(O7<=Assumptions!$B$35, Assumptions!$D$34 + (O7-Assumptions!$B$34)*Assumptions!$C$34, Assumptions!$D$35 + (O7-Assumptions!$B$35)*Assumptions!$C$35))))))) -> 2760.1517 | Q7: =L7 -> 91572.412 | R7: =IF('Capital Gains'!G7<=0, 0, MIN('Schedule A'!R7, L7)) -> 0 | S7: =MAX(0, N7 - I7) -> 0 | T7: =IF('Capital Gains'!G7<=0, 0, MAX(0, L7 - S7)) -> 91572.412 | U7: =IF(T7<=0, 0, IF((O7+T7)<=Assumptions!$B$46, 0, IF(O7>=Assumptions!$B$46, T7*Assumptions!$C$46, (O7+T7-Assumptions!$B$46)*Assumptions!$C$46))) -> 0 | V7: =IF(M7<=250000, 0, 0.038 * MIN(M7 - 250000, D7 + T7)) -> 3172.8812 | W7: =P7 + U7 + V7 -> 5933.0329 | X7: =C7 + D7 + E7 + 'Capital Gains'!F7 -> 476013.46 | Y7: =IF(MAX(0, X7 - 20500)<=0, 0, IF(MAX(0, X7 - 20500)<=Assumptions!$B$20, MAX(0, X7 - 20500)*Assumptions!$C$19, IF(MAX(0, X7 - 20500)<=Assumptions!$B$21, Assumptions!$D$20 + (MAX(0, X7 - 20500)-Assumptions!$B$20)*Assumptions!$C$20, IF(MAX(0, X7 - 20500)<=Assumptions!$B$22, Assumptions!$D$21 + (MAX(0, X7 - 20500)-Assumptions!$B$21)*Assumptions!$C$21, IF(MAX(0, X7 - 20500)<=Assumptions!$B$23, Assumptions!$D$22 + (MAX(0, X7 - 20500)-Assumptions!$B$22)*Assumptions!$C$22, IF(MAX(0, X7 - 20500)<=Assumptions!$B$24, Assumptions!$D$23 + (MAX(0, X7 - 20500)-Assumptions!$B$23)*Assumptions!$C$23, IF(MAX(0, X7 - 20500)<=Assumptions!$B$25, Assumptions!$D$24 + (MAX(0, X7 - 20500)-Assumptions!$B$25)*Assumptions!$C$24, Assumptions!$D$25 + (MAX(0, X7 - 20500)-Assumptions!$B$25)*Assumptions!$C$25))))))) -> 24973.708 | Z7: =W7 + Y7 -> 30906.741 | AA7: =H7 + MIN(J7, 'Capital Gains'!F7) -> 187096.07
A8: 2032 | B8: ='Outside Income'!D8 * 0.85 -> 45025.271 | C8: ='Outside Income'!E8 -> 54301.78 | D8: =IF('Capital Gains'!G8<=0, 0, 'Outside Income'!G8) -> 15188.669 | E8: ='Inherited and Roth IRA'!K8 -> 144757.17 | F8: =IF('Capital Gains'!F8<=0, 0, MIN(MAX(0, 'Schedule A'!P8 - D8), 'Capital Gains'!F8)) -> 132043.95 | G8: =B8 + C8 + D8 + E8 + F8 -> 391316.83 | H8: =MAX(0, MIN(400000, G8 - ((20000 + 'Schedule A'!J8 + 'Schedule A'!K8 + 'Schedule A'!L8 + 'Schedule A'!Q8 + 'Schedule A'!C8 - 0.075 * MAX(0, K8 - F8)) / 1.075))) -> 138083.7 | I8: =MAX(0, G8 - H8) -> 253233.13 | J8: =MAX(0, 400000 - G8) -> 8683.1651 | K8: =IF('Capital Gains'!G8<=0, 0, MAX(0, 'Capital Gains'!F8 - F8)) -> 113471.04 | L8: =IF('Capital Gains'!G8<=0, 0, MAX(0, K8 - J8)) -> 104787.87 | M8: =I8 + L8 -> 358021.01 | N8: ='Schedule A'!M8 -> 225374.04 | O8: =MAX(0, I8 - N8) -> 27859.091 | P8: =IF(O8<=0, 0, IF(O8<=Assumptions!$B$30, O8*Assumptions!$C$29, IF(O8<=Assumptions!$B$31, Assumptions!$D$30 + (O8-Assumptions!$B$30)*Assumptions!$C$30, IF(O8<=Assumptions!$B$32, Assumptions!$D$31 + (O8-Assumptions!$B$31)*Assumptions!$C$31, IF(O8<=Assumptions!$B$33, Assumptions!$D$32 + (O8-Assumptions!$B$32)*Assumptions!$C$32, IF(O8<=Assumptions!$B$34, Assumptions!$D$33 + (O8-Assumptions!$B$33)*Assumptions!$C$33, IF(O8<=Assumptions!$B$35, Assumptions!$D$34 + (O8-Assumptions!$B$34)*Assumptions!$C$34, Assumptions!$D$35 + (O8-Assumptions!$B$35)*Assumptions!$C$35))))))) -> 2879.0909 | Q8: =L8 -> 104787.87 | R8: =IF('Capital Gains'!G8<=0, 0, MIN('Schedule A'!R8, L8)) -> 0 | S8: =MAX(0, N8 - I8) -> 0 | T8: =IF('Capital Gains'!G8<=0, 0, MAX(0, L8 - S8)) -> 104787.87 | U8: =IF(T8<=0, 0, IF((O8+T8)<=Assumptions!$B$46, 0, IF(O8>=Assumptions!$B$46, T8*Assumptions!$C$46, (O8+T8-Assumptions!$B$46)*Assumptions!$C$46))) -> 0 | V8: =IF(M8<=250000, 0, 0.038 * MIN(M8 - 250000, D8 + T8)) -> 4104.7983 | W8: =P8 + U8 + V8 -> 6983.8892 | X8: =C8 + D8 + E8 + 'Capital Gains'!F8 -> 459762.6 | Y8: =IF(MAX(0, X8 - 20500)<=0, 0, IF(MAX(0, X8 - 20500)<=Assumptions!$B$20, MAX(0, X8 - 20500)*Assumptions!$C$19, IF(MAX(0, X8 - 20500)<=Assumptions!$B$21, Assumptions!$D$20 + (MAX(0, X8 - 20500)-Assumptions!$B$20)*Assumptions!$C$20, IF(MAX(0, X8 - 20500)<=Assumptions!$B$22, Assumptions!$D$21 + (MAX(0, X8 - 20500)-Assumptions!$B$21)*Assumptions!$C$21, IF(MAX(0, X8 - 20500)<=Assumptions!$B$23, Assumptions!$D$22 + (MAX(0, X8 - 20500)-Assumptions!$B$22)*Assumptions!$C$22, IF(MAX(0, X8 - 20500)<=Assumptions!$B$24, Assumptions!$D$23 + (MAX(0, X8 - 20500)-Assumptions!$B$23)*Assumptions!$C$23, IF(MAX(0, X8 - 20500)<=Assumptions!$B$25, Assumptions!$D$24 + (MAX(0, X8 - 20500)-Assumptions!$B$25)*Assumptions!$C$24, Assumptions!$D$25 + (MAX(0, X8 - 20500)-Assumptions!$B$25)*Assumptions!$C$25))))))) -> 23938.528 | Z8: =W8 + Y8 -> 30922.417 | AA8: =H8 + MIN(J8, 'Capital Gains'!F8) -> 146766.87
A9: 2033 | B9: ='Outside Income'!D9 * 0.85 -> 45475.523 | C9: ='Outside Income'!E9 -> 59731.958 | D9: =IF('Capital Gains'!G9<=0, 0, 'Outside Income'!G9) -> 14461.984 | E9: ='Inherited and Roth IRA'!K9 -> 0 | F9: =IF('Capital Gains'!F9<=0, 0, MIN(MAX(0, 'Schedule A'!P9 - D9), 'Capital Gains'!F9)) -> 146021.57 | G9: =B9 + C9 + D9 + E9 + F9 -> 265691.04 | H9: 0 | I9: =MAX(0, G9 - H9) -> 265691.04 | J9: 0 | K9: =IF('Capital Gains'!G9<=0, 0, MAX(0, 'Capital Gains'!F9 - F9)) -> 132981.37 | L9: =IF('Capital Gains'!G9<=0, 0, MAX(0, K9 - J9)) -> 132981.37 | M9: =I9 + L9 -> 398672.41 | N9: ='Schedule A'!M9 -> 235576.12 | O9: =MAX(0, I9 - N9) -> 30114.912 | P9: =IF(O9<=0, 0, IF(O9<=Assumptions!$B$30, O9*Assumptions!$C$29, IF(O9<=Assumptions!$B$31, Assumptions!$D$30 + (O9-Assumptions!$B$30)*Assumptions!$C$30, IF(O9<=Assumptions!$B$32, Assumptions!$D$31 + (O9-Assumptions!$B$31)*Assumptions!$C$31, IF(O9<=Assumptions!$B$33, Assumptions!$D$32 + (O9-Assumptions!$B$32)*Assumptions!$C$32, IF(O9<=Assumptions!$B$34, Assumptions!$D$33 + (O9-Assumptions!$B$33)*Assumptions!$C$33, IF(O9<=Assumptions!$B$35, Assumptions!$D$34 + (O9-Assumptions!$B$34)*Assumptions!$C$34, Assumptions!$D$35 + (O9-Assumptions!$B$35)*Assumptions!$C$35))))))) -> 3149.7894 | Q9: =L9 -> 132981.37 | R9: =IF('Capital Gains'!G9<=0, 0, MIN('Schedule A'!R9, L9)) -> 0 | S9: =MAX(0, N9 - I9) -> 0 | T9: =IF('Capital Gains'!G9<=0, 0, MAX(0, L9 - S9)) -> 132981.37 | U9: =IF(T9<=0, 0, IF((O9+T9)<=Assumptions!$B$46, 0, IF(O9>=Assumptions!$B$46, T9*Assumptions!$C$46, (O9+T9-Assumptions!$B$46)*Assumptions!$C$46))) -> 0 | V9: =IF(M9<=250000, 0, 0.038 * MIN(M9 - 250000, D9 + T9)) -> 5602.8476 | W9: =P9 + U9 + V9 -> 8752.637 | X9: =C9 + D9 + E9 + 'Capital Gains'!F9 -> 353196.89 | Y9: =IF(MAX(0, X9 - 20500)<=0, 0, IF(MAX(0, X9 - 20500)<=Assumptions!$B$20, MAX(0, X9 - 20500)*Assumptions!$C$19, IF(MAX(0, X9 - 20500)<=Assumptions!$B$21, Assumptions!$D$20 + (MAX(0, X9 - 20500)-Assumptions!$B$20)*Assumptions!$C$20, IF(MAX(0, X9 - 20500)<=Assumptions!$B$22, Assumptions!$D$21 + (MAX(0, X9 - 20500)-Assumptions!$B$21)*Assumptions!$C$21, IF(MAX(0, X9 - 20500)<=Assumptions!$B$23, Assumptions!$D$22 + (MAX(0, X9 - 20500)-Assumptions!$B$22)*Assumptions!$C$22, IF(MAX(0, X9 - 20500)<=Assumptions!$B$24, Assumptions!$D$23 + (MAX(0, X9 - 20500)-Assumptions!$B$23)*Assumptions!$C$23, IF(MAX(0, X9 - 20500)<=Assumptions!$B$25, Assumptions!$D$24 + (MAX(0, X9 - 20500)-Assumptions!$B$25)*Assumptions!$C$24, Assumptions!$D$25 + (MAX(0, X9 - 20500)-Assumptions!$B$25)*Assumptions!$C$25))))))) -> 17150.292 | Z9: =W9 + Y9 -> 25902.929 | AA9: =H9 + MIN(J9, 'Capital Gains'!F9) -> 0
A10: 2034 | B10: ='Outside Income'!D10 * 0.85 -> 45930.278 | C10: ='Outside Income'!E10 -> 65705.154 | D10: =IF('Capital Gains'!G10<=0, 0, 'Outside Income'!G10) -> 13584.213 | E10: ='Inherited and Roth IRA'!K10 -> 0 | F10: =IF('Capital Gains'!F10<=0, 0, MIN(MAX(0, 'Schedule A'!P10 - D10), 'Capital Gains'!F10)) -> 161342.86 | G10: =B10 + C10 + D10 + E10 + F10 -> 286562.51 | H10: 0 | I10: =MAX(0, G10 - H10) -> 286562.51 | J10: 0 | K10: =IF('Capital Gains'!G10<=0, 0, MAX(0, 'Capital Gains'!F10 - F10)) -> 150032.5 | L10: =IF('Capital Gains'!G10<=0, 0, MAX(0, K10 - J10)) -> 150032.5 | M10: =I10 + L10 -> 436595.01 | N10: ='Schedule A'!M10 -> 247175.45 | O10: =MAX(0, I10 - N10) -> 39387.058 | P10: =IF(O10<=0, 0, IF(O10<=Assumptions!$B$30, O10*Assumptions!$C$29, IF(O10<=Assumptions!$B$31, Assumptions!$D$30 + (O10-Assumptions!$B$30)*Assumptions!$C$30, IF(O10<=Assumptions!$B$32, Assumptions!$D$31 + (O10-Assumptions!$B$31)*Assumptions!$C$31, IF(O10<=Assumptions!$B$33, Assumptions!$D$32 + (O10-Assumptions!$B$32)*Assumptions!$C$32, IF(O10<=Assumptions!$B$34, Assumptions!$D$33 + (O10-Assumptions!$B$33)*Assumptions!$C$33, IF(O10<=Assumptions!$B$35, Assumptions!$D$34 + (O10-Assumptions!$B$34)*Assumptions!$C$34, Assumptions!$D$35 + (O10-Assumptions!$B$35)*Assumptions!$C$35))))))) -> 4262.447 | Q10: =L10 -> 150032.5 | R10: =IF('Capital Gains'!G10<=0, 0, MIN('Schedule A'!R10, L10)) -> 0 | S10: =MAX(0, N10 - I10) -> 0 | T10: =IF('Capital Gains'!G10<=0, 0, MAX(0, L10 - S10)) -> 150032.5 | U10: =IF(T10<=0, 0, IF((O10+T10)<=Assumptions!$B$46, 0, IF(O10>=Assumptions!$B$46, T10*Assumptions!$C$46, (O10+T10-Assumptions!$B$46)*Assumptions!$C$46))) -> 0 | V10: =IF(M10<=250000, 0, 0.038 * MIN(M10 - 250000, D10 + T10)) -> 6217.4351 | W10: =P10 + U10 + V10 -> 10479.882 | X10: =C10 + D10 + E10 + 'Capital Gains'!F10 -> 390664.73 | Y10: =IF(MAX(0, X10 - 20500)<=0, 0, IF(MAX(0, X10 - 20500)<=Assumptions!$B$20, MAX(0, X10 - 20500)*Assumptions!$C$19, IF(MAX(0, X10 - 20500)<=Assumptions!$B$21, Assumptions!$D$20 + (MAX(0, X10 - 20500)-Assumptions!$B$20)*Assumptions!$C$20, IF(MAX(0, X10 - 20500)<=Assumptions!$B$22, Assumptions!$D$21 + (MAX(0, X10 - 20500)-Assumptions!$B$21)*Assumptions!$C$21, IF(MAX(0, X10 - 20500)<=Assumptions!$B$23, Assumptions!$D$22 + (MAX(0, X10 - 20500)-Assumptions!$B$22)*Assumptions!$C$22, IF(MAX(0, X10 - 20500)<=Assumptions!$B$24, Assumptions!$D$23 + (MAX(0, X10 - 20500)-Assumptions!$B$23)*Assumptions!$C$23, IF(MAX(0, X10 - 20500)<=Assumptions!$B$25, Assumptions!$D$24 + (MAX(0, X10 - 20500)-Assumptions!$B$25)*Assumptions!$C$24, Assumptions!$D$25 + (MAX(0, X10 - 20500)-Assumptions!$B$25)*Assumptions!$C$25))))))) -> 19536.993 | Z10: =W10 + Y10 -> 30016.875 | AA10: =H10 + MIN(J10, 'Capital Gains'!F10) -> 0
A11: 2035 | B11: ='Outside Income'!D11 * 0.85 -> 46389.581 | C11: ='Outside Income'!E11 -> 72275.669 | D11: =IF('Capital Gains'!G11<=0, 0, 'Outside Income'!G11) -> 12538.364 | E11: ='Inherited and Roth IRA'!K11 -> 0 | F11: =IF('Capital Gains'!F11<=0, 0, MIN(MAX(0, 'Schedule A'!P11 - D11), 'Capital Gains'!F11)) -> 178132.15 | G11: =B11 + C11 + D11 + E11 + F11 -> 309335.76 | H11: 0 | I11: =MAX(0, G11 - H11) -> 309335.76 | J11: 0 | K11: =IF('Capital Gains'!G11<=0, 0, MAX(0, 'Capital Gains'!F11 - F11)) -> 164535.04 | L11: =IF('Capital Gains'!G11<=0, 0, MAX(0, K11 - J11)) -> 164535.04 | M11: =I11 + L11 -> 473870.8 | N11: ='Schedule A'!M11 -> 260123.2 | O11: =MAX(0, I11 - N11) -> 49212.56 | P11: =IF(O11<=0, 0, IF(O11<=Assumptions!$B$30, O11*Assumptions!$C$29, IF(O11<=Assumptions!$B$31, Assumptions!$D$30 + (O11-Assumptions!$B$30)*Assumptions!$C$30, IF(O11<=Assumptions!$B$32, Assumptions!$D$31 + (O11-Assumptions!$B$31)*Assumptions!$C$31, IF(O11<=Assumptions!$B$33, Assumptions!$D$32 + (O11-Assumptions!$B$32)*Assumptions!$C$32, IF(O11<=Assumptions!$B$34, Assumptions!$D$33 + (O11-Assumptions!$B$33)*Assumptions!$C$33, IF(O11<=Assumptions!$B$35, Assumptions!$D$34 + (O11-Assumptions!$B$34)*Assumptions!$C$34, Assumptions!$D$35 + (O11-Assumptions!$B$35)*Assumptions!$C$35))))))) -> 5441.5072 | Q11: =L11 -> 164535.04 | R11: =IF('Capital Gains'!G11<=0, 0, MIN('Schedule A'!R11, L11)) -> 0 | S11: =MAX(0, N11 - I11) -> 0 | T11: =IF('Capital Gains'!G11<=0, 0, MAX(0, L11 - S11)) -> 164535.04 | U11: =IF(T11<=0, 0, IF((O11+T11)<=Assumptions!$B$46, 0, IF(O11>=Assumptions!$B$46, T11*Assumptions!$C$46, (O11+T11-Assumptions!$B$46)*Assumptions!$C$46))) -> 0 | V11: =IF(M11<=250000, 0, 0.038 * MIN(M11 - 250000, D11 + T11)) -> 6728.7892 | W11: =P11 + U11 + V11 -> 12170.296 | X11: =C11 + D11 + E11 + 'Capital Gains'!F11 -> 427481.22 | Y11: =IF(MAX(0, X11 - 20500)<=0, 0, IF(MAX(0, X11 - 20500)<=Assumptions!$B$20, MAX(0, X11 - 20500)*Assumptions!$C$19, IF(MAX(0, X11 - 20500)<=Assumptions!$B$21, Assumptions!$D$20 + (MAX(0, X11 - 20500)-Assumptions!$B$20)*Assumptions!$C$20, IF(MAX(0, X11 - 20500)<=Assumptions!$B$22, Assumptions!$D$21 + (MAX(0, X11 - 20500)-Assumptions!$B$21)*Assumptions!$C$21, IF(MAX(0, X11 - 20500)<=Assumptions!$B$23, Assumptions!$D$22 + (MAX(0, X11 - 20500)-Assumptions!$B$22)*Assumptions!$C$22, IF(MAX(0, X11 - 20500)<=Assumptions!$B$24, Assumptions!$D$23 + (MAX(0, X11 - 20500)-Assumptions!$B$23)*Assumptions!$C$23, IF(MAX(0, X11 - 20500)<=Assumptions!$B$25, Assumptions!$D$24 + (MAX(0, X11 - 20500)-Assumptions!$B$25)*Assumptions!$C$24, Assumptions!$D$25 + (MAX(0, X11 - 20500)-Assumptions!$B$25)*Assumptions!$C$25))))))) -> 21882.203 | Z11: =W11 + Y11 -> 34052.5 | AA11: =H11 + MIN(J11, 'Capital Gains'!F11) -> 0
A12: 2036 | B12: ='Outside Income'!D12 * 0.85 -> 46853.477 | C12: ='Outside Income'!E12 -> 79503.236 | D12: =IF('Capital Gains'!G12<=0, 0, 'Outside Income'!G12) -> 11305.749 | E12: ='Inherited and Roth IRA'!K12 | F12: =IF('Capital Gains'!F12<=0, 0, MIN(MAX(0, 'Schedule A'!P12 - D12), 'Capital Gains'!F12)) -> 196525.11 | G12: =B12 + C12 + D12 + E12 + F12 -> 334187.57 | H12: 0 | I12: =MAX(0, G12 - H12) -> 334187.57 | J12: 0 | K12: =IF('Capital Gains'!G12<=0, 0, MAX(0, 'Capital Gains'!F12 - F12)) -> 176379.8 | L12: =IF('Capital Gains'!G12<=0, 0, MAX(0, K12 - J12)) -> 176379.8 | M12: =I12 + L12 -> 510567.37 | N12: ='Schedule A'!M12 -> 274531.3 | O12: =MAX(0, I12 - N12) -> 59656.266 | P12: =IF(O12<=0, 0, IF(O12<=Assumptions!$B$30, O12*Assumptions!$C$29, IF(O12<=Assumptions!$B$31, Assumptions!$D$30 + (O12-Assumptions!$B$30)*Assumptions!$C$30, IF(O12<=Assumptions!$B$32, Assumptions!$D$31 + (O12-Assumptions!$B$31)*Assumptions!$C$31, IF(O12<=Assumptions!$B$33, Assumptions!$D$32 + (O12-Assumptions!$B$32)*Assumptions!$C$32, IF(O12<=Assumptions!$B$34, Assumptions!$D$33 + (O12-Assumptions!$B$33)*Assumptions!$C$33, IF(O12<=Assumptions!$B$35, Assumptions!$D$34 + (O12-Assumptions!$B$34)*Assumptions!$C$34, Assumptions!$D$35 + (O12-Assumptions!$B$35)*Assumptions!$C$35))))))) -> 6694.7519 | Q12: =L12 -> 176379.8 | R12: =IF('Capital Gains'!G12<=0, 0, MIN('Schedule A'!R12, L12)) -> 0 | S12: =MAX(0, N12 - I12) -> 0 | T12: =IF('Capital Gains'!G12<=0, 0, MAX(0, L12 - S12)) -> 176379.8 | U12: =IF(T12<=0, 0, IF((O12+T12)<=Assumptions!$B$46, 0, IF(O12>=Assumptions!$B$46, T12*Assumptions!$C$46, (O12+T12-Assumptions!$B$46)*Assumptions!$C$46))) -> 0 | V12: =IF(M12<=250000, 0, 0.038 * MIN(M12 - 250000, D12 + T12)) -> 7132.0507 | W12: =P12 + U12 + V12 -> 13826.803 | X12: =C12 + D12 + E12 + 'Capital Gains'!F12 -> 463713.89 | Y12: =IF(MAX(0, X12 - 20500)<=0, 0, IF(MAX(0, X12 - 20500)<=Assumptions!$B$20, MAX(0, X12 - 20500)*Assumptions!$C$19, IF(MAX(0, X12 - 20500)<=Assumptions!$B$21, Assumptions!$D$20 + (MAX(0, X12 - 20500)-Assumptions!$B$20)*Assumptions!$C$20, IF(MAX(0, X12 - 20500)<=Assumptions!$B$22, Assumptions!$D$21 + (MAX(0, X12 - 20500)-Assumptions!$B$21)*Assumptions!$C$21, IF(MAX(0, X12 - 20500)<=Assumptions!$B$23, Assumptions!$D$22 + (MAX(0, X12 - 20500)-Assumptions!$B$22)*Assumptions!$C$22, IF(MAX(0, X12 - 20500)<=Assumptions!$B$24, Assumptions!$D$23 + (MAX(0, X12 - 20500)-Assumptions!$B$23)*Assumptions!$C$23, IF(MAX(0, X12 - 20500)<=Assumptions!$B$25, Assumptions!$D$24 + (MAX(0, X12 - 20500)-Assumptions!$B$25)*Assumptions!$C$24, Assumptions!$D$25 + (MAX(0, X12 - 20500)-Assumptions!$B$25)*Assumptions!$C$25))))))) -> 24190.225 | Z12: =W12 + Y12 -> 38017.027 | AA12: =H12 + MIN(J12, 'Capital Gains'!F12) -> 0
A13: 2037 | B13: ='Outside Income'!D13 * 0.85 -> 47322.012 | C13: ='Outside Income'!E13 -> 87453.56 | D13: =IF('Capital Gains'!G13<=0, 0, 'Outside Income'!G13) -> 9865.8146 | E13: ='Inherited and Roth IRA'!K13 | F13: =IF('Capital Gains'!F13<=0, 0, MIN(MAX(0, 'Schedule A'!P13 - D13), 'Capital Gains'!F13)) -> 216669.82 | G13: =B13 + C13 + D13 + E13 + F13 -> 361311.21 | H13: 0 | I13: =MAX(0, G13 - H13) -> 361311.21 | J13: 0 | K13: =IF('Capital Gains'!G13<=0, 0, MAX(0, 'Capital Gains'!F13 - F13)) -> 185436.36 | L13: =IF('Capital Gains'!G13<=0, 0, MAX(0, K13 - J13)) -> 185436.36 | M13: =I13 + L13 -> 546747.56 | N13: ='Schedule A'!M13 -> 290522.57 | O13: =MAX(0, I13 - N13) -> 70788.639 | P13: =IF(O13<=0, 0, IF(O13<=Assumptions!$B$30, O13*Assumptions!$C$29, IF(O13<=Assumptions!$B$31, Assumptions!$D$30 + (O13-Assumptions!$B$30)*Assumptions!$C$30, IF(O13<=Assumptions!$B$32, Assumptions!$D$31 + (O13-Assumptions!$B$31)*Assumptions!$C$31, IF(O13<=Assumptions!$B$33, Assumptions!$D$32 + (O13-Assumptions!$B$32)*Assumptions!$C$32, IF(O13<=Assumptions!$B$34, Assumptions!$D$33 + (O13-Assumptions!$B$33)*Assumptions!$C$33, IF(O13<=Assumptions!$B$35, Assumptions!$D$34 + (O13-Assumptions!$B$34)*Assumptions!$C$34, Assumptions!$D$35 + (O13-Assumptions!$B$35)*Assumptions!$C$35))))))) -> 8030.6367 | Q13: =L13 -> 185436.36 | R13: =IF('Capital Gains'!G13<=0, 0, MIN('Schedule A'!R13, L13)) -> 0 | S13: =MAX(0, N13 - I13) -> 0 | T13: =IF('Capital Gains'!G13<=0, 0, MAX(0, L13 - S13)) -> 185436.36 | U13: =IF(T13<=0, 0, IF((O13+T13)<=Assumptions!$B$46, 0, IF(O13>=Assumptions!$B$46, T13*Assumptions!$C$46, (O13+T13-Assumptions!$B$46)*Assumptions!$C$46))) -> 0 | V13: =IF(M13<=250000, 0, 0.038 * MIN(M13 - 250000, D13 + T13)) -> 7421.4825 | W13: =P13 + U13 + V13 -> 15452.119 | X13: =C13 + D13 + E13 + 'Capital Gains'!F13 -> 499425.55 | Y13: =IF(MAX(0, X13 - 20500)<=0, 0, IF(MAX(0, X13 - 20500)<=Assumptions!$B$20, MAX(0, X13 - 20500)*Assumptions!$C$19, IF(MAX(0, X13 - 20500)<=Assumptions!$B$21, Assumptions!$D$20 + (MAX(0, X13 - 20500)-Assumptions!$B$20)*Assumptions!$C$20, IF(MAX(0, X13 - 20500)<=Assumptions!$B$22, Assumptions!$D$21 + (MAX(0, X13 - 20500)-Assumptions!$B$21)*Assumptions!$C$21, IF(MAX(0, X13 - 20500)<=Assumptions!$B$23, Assumptions!$D$22 + (MAX(0, X13 - 20500)-Assumptions!$B$22)*Assumptions!$C$22, IF(MAX(0, X13 - 20500)<=Assumptions!$B$24, Assumptions!$D$23 + (MAX(0, X13 - 20500)-Assumptions!$B$23)*Assumptions!$C$23, IF(MAX(0, X13 - 20500)<=Assumptions!$B$25, Assumptions!$D$24 + (MAX(0, X13 - 20500)-Assumptions!$B$25)*Assumptions!$C$24, Assumptions!$D$25 + (MAX(0, X13 - 20500)-Assumptions!$B$25)*Assumptions!$C$25))))))) -> 26465.058 | Z13: =W13 + Y13 -> 41917.177 | AA13: =H13 + MIN(J13, 'Capital Gains'!F13) -> 0
A14: 2038 | B14: ='Outside Income'!D14 * 0.85 -> 47795.232 | C14: ='Outside Income'!E14 -> 96198.916 | D14: =IF('Capital Gains'!G14<=0, 0, 'Outside Income'!G14) -> 8195.9673 | E14: ='Inherited and Roth IRA'!K14 | F14: =IF('Capital Gains'!F14<=0, 0, MIN(MAX(0, 'Schedule A'!P14 - D14), 'Capital Gains'!F14)) -> 238727.87 | G14: =B14 + C14 + D14 + E14 + F14 -> 390917.99 | H14: 0 | I14: =MAX(0, G14 - H14) -> 390917.99 | J14: 0 | K14: =IF('Capital Gains'!G14<=0, 0, MAX(0, 'Capital Gains'!F14 - F14)) -> 191551.45 | L14: =IF('Capital Gains'!G14<=0, 0, MAX(0, K14 - J14)) -> 191551.45 | M14: =I14 + L14 -> 582469.44 | N14: ='Schedule A'!M14 -> 308231.63 | O14: =MAX(0, I14 - N14) -> 82686.356 | P14: =IF(O14<=0, 0, IF(O14<=Assumptions!$B$30, O14*Assumptions!$C$29, IF(O14<=Assumptions!$B$31, Assumptions!$D$30 + (O14-Assumptions!$B$30)*Assumptions!$C$30, IF(O14<=Assumptions!$B$32, Assumptions!$D$31 + (O14-Assumptions!$B$31)*Assumptions!$C$31, IF(O14<=Assumptions!$B$33, Assumptions!$D$32 + (O14-Assumptions!$B$32)*Assumptions!$C$32, IF(O14<=Assumptions!$B$34, Assumptions!$D$33 + (O14-Assumptions!$B$33)*Assumptions!$C$33, IF(O14<=Assumptions!$B$35, Assumptions!$D$34 + (O14-Assumptions!$B$34)*Assumptions!$C$34, Assumptions!$D$35 + (O14-Assumptions!$B$35)*Assumptions!$C$35))))))) -> 9458.3627 | Q14: =L14 -> 191551.45 | R14: =IF('Capital Gains'!G14<=0, 0, MIN('Schedule A'!R14, L14)) -> 0 | S14: =MAX(0, N14 - I14) -> 0 | T14: =IF('Capital Gains'!G14<=0, 0, MAX(0, L14 - S14)) -> 191551.45 | U14: =IF(T14<=0, 0, IF((O14+T14)<=Assumptions!$B$46, 0, IF(O14>=Assumptions!$B$46, T14*Assumptions!$C$46, (O14+T14-Assumptions!$B$46)*Assumptions!$C$46))) -> 0 | V14: =IF(M14<=250000, 0, 0.038 * MIN(M14 - 250000, D14 + T14)) -> 7590.4019 | W14: =P14 + U14 + V14 -> 17048.765 | X14: =C14 + D14 + E14 + 'Capital Gains'!F14 -> 534674.21 | Y14: =IF(MAX(0, X14 - 20500)<=0, 0, IF(MAX(0, X14 - 20500)<=Assumptions!$B$20, MAX(0, X14 - 20500)*Assumptions!$C$19, IF(MAX(0, X14 - 20500)<=Assumptions!$B$21, Assumptions!$D$20 + (MAX(0, X14 - 20500)-Assumptions!$B$20)*Assumptions!$C$20, IF(MAX(0, X14 - 20500)<=Assumptions!$B$22, Assumptions!$D$21 + (MAX(0, X14 - 20500)-Assumptions!$B$21)*Assumptions!$C$21, IF(MAX(0, X14 - 20500)<=Assumptions!$B$23, Assumptions!$D$22 + (MAX(0, X14 - 20500)-Assumptions!$B$22)*Assumptions!$C$22, IF(MAX(0, X14 - 20500)<=Assumptions!$B$24, Assumptions!$D$23 + (MAX(0, X14 - 20500)-Assumptions!$B$23)*Assumptions!$C$23, IF(MAX(0, X14 - 20500)<=Assumptions!$B$25, Assumptions!$D$24 + (MAX(0, X14 - 20500)-Assumptions!$B$25)*Assumptions!$C$24, Assumptions!$D$25 + (MAX(0, X14 - 20500)-Assumptions!$B$25)*Assumptions!$C$25))))))) -> 28710.397 | Z14: =W14 + Y14 -> 45759.162 | AA14: =H14 + MIN(J14, 'Capital Gains'!F14) -> 0
A15: 2039 | B15: ='Outside Income'!D15 * 0.85 -> 48273.184 | C15: ='Outside Income'!E15 -> 105818.81 | D15: =IF('Capital Gains'!G15<=0, 0, 'Outside Income'!G15) -> 6271.3744 | E15: ='Inherited and Roth IRA'!K15 | F15: =IF('Capital Gains'!F15<=0, 0, MIN(MAX(0, 'Schedule A'!P15 - D15), 'Capital Gains'!F15)) -> 262875.61 | G15: =B15 + C15 + D15 + E15 + F15 -> 423238.98 | H15: 0 | I15: =MAX(0, G15 - H15) -> 423238.98 | J15: 0 | K15: =IF('Capital Gains'!G15<=0, 0, MAX(0, 'Capital Gains'!F15 - F15)) -> 194547.24 | L15: =IF('Capital Gains'!G15<=0, 0, MAX(0, K15 - J15)) -> 194547.24 | M15: =I15 + L15 -> 617786.22 | N15: ='Schedule A'!M15 -> 327806.02 | O15: =MAX(0, I15 - N15) -> 95432.958 | P15: =IF(O15<=0, 0, IF(O15<=Assumptions!$B$30, O15*Assumptions!$C$29, IF(O15<=Assumptions!$B$31, Assumptions!$D$30 + (O15-Assumptions!$B$30)*Assumptions!$C$30, IF(O15<=Assumptions!$B$32, Assumptions!$D$31 + (O15-Assumptions!$B$31)*Assumptions!$C$31, IF(O15<=Assumptions!$B$33, Assumptions!$D$32 + (O15-Assumptions!$B$32)*Assumptions!$C$32, IF(O15<=Assumptions!$B$34, Assumptions!$D$33 + (O15-Assumptions!$B$33)*Assumptions!$C$33, IF(O15<=Assumptions!$B$35, Assumptions!$D$34 + (O15-Assumptions!$B$34)*Assumptions!$C$34, Assumptions!$D$35 + (O15-Assumptions!$B$35)*Assumptions!$C$35))))))) -> 11101.251 | Q15: =L15 -> 194547.24 | R15: =IF('Capital Gains'!G15<=0, 0, MIN('Schedule A'!R15, L15)) -> 0 | S15: =MAX(0, N15 - I15) -> 0 | T15: =IF('Capital Gains'!G15<=0, 0, MAX(0, L15 - S15)) -> 194547.24 | U15: =IF(T15<=0, 0, IF((O15+T15)<=Assumptions!$B$46, 0, IF(O15>=Assumptions!$B$46, T15*Assumptions!$C$46, (O15+T15-Assumptions!$B$46)*Assumptions!$C$46))) -> 0 | V15: =IF(M15<=250000, 0, 0.038 * MIN(M15 - 250000, D15 + T15)) -> 7631.1073 | W15: =P15 + U15 + V15 -> 18732.358 | X15: =C15 + D15 + E15 + 'Capital Gains'!F15 -> 569513.03 | Y15: =IF(MAX(0, X15 - 20500)<=0, 0, IF(MAX(0, X15 - 20500)<=Assumptions!$B$20, MAX(0, X15 - 20500)*Assumptions!$C$19, IF(MAX(0, X15 - 20500)<=Assumptions!$B$21, Assumptions!$D$20 + (MAX(0, X15 - 20500)-Assumptions!$B$20)*Assumptions!$C$20, IF(MAX(0, X15 - 20500)<=Assumptions!$B$22, Assumptions!$D$21 + (MAX(0, X15 - 20500)-Assumptions!$B$21)*Assumptions!$C$21, IF(MAX(0, X15 - 20500)<=Assumptions!$B$23, Assumptions!$D$22 + (MAX(0, X15 - 20500)-Assumptions!$B$22)*Assumptions!$C$22, IF(MAX(0, X15 - 20500)<=Assumptions!$B$24, Assumptions!$D$23 + (MAX(0, X15 - 20500)-Assumptions!$B$23)*Assumptions!$C$23, IF(MAX(0, X15 - 20500)<=Assumptions!$B$25, Assumptions!$D$24 + (MAX(0, X15 - 20500)-Assumptions!$B$25)*Assumptions!$C$24, Assumptions!$D$25 + (MAX(0, X15 - 20500)-Assumptions!$B$25)*Assumptions!$C$25))))))) -> 30929.63 | Z15: =W15 + Y15 -> 49661.988 | AA15: =H15 + MIN(J15, 'Capital Gains'!F15) -> 0
A16: 2040 | B16: ='Outside Income'!D16 * 0.85 -> 48755.916 | C16: ='Outside Income'!E16 -> 116400.69 | D16: =IF('Capital Gains'!G16<=0, 0, 'Outside Income'!G16) -> 4064.7509 | E16: ='Inherited and Roth IRA'!K16 | F16: =IF('Capital Gains'!F16<=0, 0, MIN(MAX(0, 'Schedule A'!P16 - D16), 'Capital Gains'!F16)) -> 289305.46 | G16: =B16 + C16 + D16 + E16 + F16 -> 458526.82 | H16: 0 | I16: =MAX(0, G16 - H16) -> 458526.82 | J16: 0 | K16: =IF('Capital Gains'!G16<=0, 0, MAX(0, 'Capital Gains'!F16 - F16)) -> 194219.37 | L16: =IF('Capital Gains'!G16<=0, 0, MAX(0, K16 - J16)) -> 194219.37 | M16: =I16 + L16 -> 652746.19 | N16: ='Schedule A'!M16 -> 349407.25 | O16: =MAX(0, I16 - N16) -> 109119.57 | P16: =IF(O16<=0, 0, IF(O16<=Assumptions!$B$30, O16*Assumptions!$C$29, IF(O16<=Assumptions!$B$31, Assumptions!$D$30 + (O16-Assumptions!$B$30)*Assumptions!$C$30, IF(O16<=Assumptions!$B$32, Assumptions!$D$31 + (O16-Assumptions!$B$31)*Assumptions!$C$31, IF(O16<=Assumptions!$B$33, Assumptions!$D$32 + (O16-Assumptions!$B$32)*Assumptions!$C$32, IF(O16<=Assumptions!$B$34, Assumptions!$D$33 + (O16-Assumptions!$B$33)*Assumptions!$C$33, IF(O16<=Assumptions!$B$35, Assumptions!$D$34 + (O16-Assumptions!$B$34)*Assumptions!$C$34, Assumptions!$D$35 + (O16-Assumptions!$B$35)*Assumptions!$C$35))))))) -> 14112.305 | Q16: =L16 -> 194219.37 | R16: =IF('Capital Gains'!G16<=0, 0, MIN('Schedule A'!R16, L16)) -> 0 | S16: =MAX(0, N16 - I16) -> 0 | T16: =IF('Capital Gains'!G16<=0, 0, MAX(0, L16 - S16)) -> 194219.37 | U16: =IF(T16<=0, 0, IF((O16+T16)<=Assumptions!$B$46, 0, IF(O16>=Assumptions!$B$46, T16*Assumptions!$C$46, (O16+T16-Assumptions!$B$46)*Assumptions!$C$46))) -> 0 | V16: =IF(M16<=250000, 0, 0.038 * MIN(M16 - 250000, D16 + T16)) -> 7534.7967 | W16: =P16 + U16 + V16 -> 21647.102 | X16: =C16 + D16 + E16 + 'Capital Gains'!F16 -> 603990.28 | Y16: =IF(MAX(0, X16 - 20500)<=0, 0, IF(MAX(0, X16 - 20500)<=Assumptions!$B$20, MAX(0, X16 - 20500)*Assumptions!$C$19, IF(MAX(0, X16 - 20500)<=Assumptions!$B$21, Assumptions!$D$20 + (MAX(0, X16 - 20500)-Assumptions!$B$20)*Assumptions!$C$20, IF(MAX(0, X16 - 20500)<=Assumptions!$B$22, Assumptions!$D$21 + (MAX(0, X16 - 20500)-Assumptions!$B$21)*Assumptions!$C$21, IF(MAX(0, X16 - 20500)<=Assumptions!$B$23, Assumptions!$D$22 + (MAX(0, X16 - 20500)-Assumptions!$B$22)*Assumptions!$C$22, IF(MAX(0, X16 - 20500)<=Assumptions!$B$24, Assumptions!$D$23 + (MAX(0, X16 - 20500)-Assumptions!$B$23)*Assumptions!$C$23, IF(MAX(0, X16 - 20500)<=Assumptions!$B$25, Assumptions!$D$24 + (MAX(0, X16 - 20500)-Assumptions!$B$25)*Assumptions!$C$24, Assumptions!$D$25 + (MAX(0, X16 - 20500)-Assumptions!$B$25)*Assumptions!$C$25))))))) -> 33125.831 | Z16: =W16 + Y16 -> 54772.932 | AA16: =H16 + MIN(J16, 'Capital Gains'!F16) -> 0
A17: 2041 | B17: ='Outside Income'!D17 * 0.85 -> 49243.475 | C17: ='Outside Income'!E17 -> 128040.76 | D17: =IF('Capital Gains'!G17<=0, 0, 'Outside Income'!G17) -> 1546.1239 | E17: ='Inherited and Roth IRA'!K17 | F17: =IF('Capital Gains'!F17<=0, 0, MIN(MAX(0, 'Schedule A'!P17 - D17), 'Capital Gains'!F17)) -> 287706.77 | G17: =B17 + C17 + D17 + E17 + F17 -> 466537.12 | H17: 0 | I17: =MAX(0, G17 - H17) -> 466537.12 | J17: 0 | K17: =IF('Capital Gains'!G17<=0, 0, MAX(0, 'Capital Gains'!F17 - F17)) -> 0 | L17: =IF('Capital Gains'!G17<=0, 0, MAX(0, K17 - J17)) -> 0 | M17: =I17 + L17 -> 466537.12 | N17: ='Schedule A'!M17 -> 359255.61 | O17: =MAX(0, I17 - N17) -> 107281.52 | P17: =IF(O17<=0, 0, IF(O17<=Assumptions!$B$30, O17*Assumptions!$C$29, IF(O17<=Assumptions!$B$31, Assumptions!$D$30 + (O17-Assumptions!$B$30)*Assumptions!$C$30, IF(O17<=Assumptions!$B$32, Assumptions!$D$31 + (O17-Assumptions!$B$31)*Assumptions!$C$31, IF(O17<=Assumptions!$B$33, Assumptions!$D$32 + (O17-Assumptions!$B$32)*Assumptions!$C$32, IF(O17<=Assumptions!$B$34, Assumptions!$D$33 + (O17-Assumptions!$B$33)*Assumptions!$C$33, IF(O17<=Assumptions!$B$35, Assumptions!$D$34 + (O17-Assumptions!$B$34)*Assumptions!$C$34, Assumptions!$D$35 + (O17-Assumptions!$B$35)*Assumptions!$C$35))))))) -> 13707.934 | Q17: =L17 -> 0 | R17: =IF('Capital Gains'!G17<=0, 0, MIN('Schedule A'!R17, L17)) -> 0 | S17: =MAX(0, N17 - I17) -> 0 | T17: =IF('Capital Gains'!G17<=0, 0, MAX(0, L17 - S17)) -> 0 | U17: =IF(T17<=0, 0, IF((O17+T17)<=Assumptions!$B$46, 0, IF(O17>=Assumptions!$B$46, T17*Assumptions!$C$46, (O17+T17-Assumptions!$B$46)*Assumptions!$C$46))) -> 0 | V17: =IF(M17<=250000, 0, 0.038 * MIN(M17 - 250000, D17 + T17)) -> 58.75271 | W17: =P17 + U17 + V17 -> 13766.686 | X17: =C17 + D17 + E17 + 'Capital Gains'!F17 -> 417293.65 | Y17: =IF(MAX(0, X17 - 20500)<=0, 0, IF(MAX(0, X17 - 20500)<=Assumptions!$B$20, MAX(0, X17 - 20500)*Assumptions!$C$19, IF(MAX(0, X17 - 20500)<=Assumptions!$B$21, Assumptions!$D$20 + (MAX(0, X17 - 20500)-Assumptions!$B$20)*Assumptions!$C$20, IF(MAX(0, X17 - 20500)<=Assumptions!$B$22, Assumptions!$D$21 + (MAX(0, X17 - 20500)-Assumptions!$B$21)*Assumptions!$C$21, IF(MAX(0, X17 - 20500)<=Assumptions!$B$23, Assumptions!$D$22 + (MAX(0, X17 - 20500)-Assumptions!$B$22)*Assumptions!$C$22, IF(MAX(0, X17 - 20500)<=Assumptions!$B$24, Assumptions!$D$23 + (MAX(0, X17 - 20500)-Assumptions!$B$23)*Assumptions!$C$23, IF(MAX(0, X17 - 20500)<=Assumptions!$B$25, Assumptions!$D$24 + (MAX(0, X17 - 20500)-Assumptions!$B$25)*Assumptions!$C$24, Assumptions!$D$25 + (MAX(0, X17 - 20500)-Assumptions!$B$25)*Assumptions!$C$25))))))) -> 21233.255 | Z17: =W17 + Y17 -> 34999.942 | AA17: =H17 + MIN(J17, 'Capital Gains'!F17) -> 0
